<mujoco model="ur5e scene">
  <compiler angle="radian" meshdir="ur5e/assets" autolimits="true"/>
  <statistic center="0.3 0 0.4" extent="0.8"/>

  <visual>
    <headlight diffuse="0.6 0.6 0.6" ambient="0.1 0.1 0.1" specular="0 0 0"/>
    <rgba haze="0.15 0.25 0.35 1"/>
    <global azimuth="120" elevation="-20"/>
  </visual>

  <asset>
    <texture type="skybox" builtin="gradient" rgb1="0.3 0.5 0.7" rgb2="0 0 0" width="512" height="3072"/>
    <texture type="2d" name="groundplane" builtin="checker" mark="edge" rgb1="0.2 0.3 0.4" rgb2="0.1 0.2 0.3" markrgb="0.8 0.8 0.8" width="300" height="300"/>
    <material name="groundplane" texture="groundplane" texuniform="true" texrepeat="5 5" reflectance="0.2"/>
  <material class="ur5e" name="black" rgba="0.033 0.033 0.033 1"/>
    <material class="ur5e" name="jointgray" rgba="0.278 0.278 0.278 1"/>
    <material class="ur5e" name="linkgray" rgba="0.82 0.82 0.82 1"/>
    <material class="ur5e" name="urblue" rgba="0.49 0.678 0.8 1"/>
    <mesh file="base_0.obj"/>
    <mesh file="base_1.obj"/>
    <mesh file="shoulder_0.obj"/>
    <mesh file="shoulder_1.obj"/>
    <mesh file="shoulder_2.obj"/>
    <mesh file="upperarm_0.obj"/>
    <mesh file="upperarm_1.obj"/>
    <mesh file="upperarm_2.obj"/>
    <mesh file="upperarm_3.obj"/>
    <mesh file="forearm_0.obj"/>
    <mesh file="forearm_1.obj"/>
    <mesh file="forearm_2.obj"/>
    <mesh file="forearm_3.obj"/>
    <mesh file="wrist1_0.obj"/>
    <mesh file="wrist1_1.obj"/>
    <mesh file="wrist1_2.obj"/>
    <mesh file="wrist2_0.obj"/>
    <mesh file="wrist2_1.obj"/>
    <mesh file="wrist2_2.obj"/>
    <mesh file="wrist3.obj"/>
  <mesh name="tool_mesh" file="screwdriver.obj"/> 
  <mesh name="table_grip_mesh" file="table_grip.obj"/> 
  </asset>

  <worldbody>
    <light pos="0 0 1.5" dir="0 0 -1" directional="true"/>
    <geom name="floor" size="0 0 0.05" type="plane" material="groundplane"/>
    <!-- Definition of the world frame -->
    <body name="world_frame" pos="0.0 0.0 0.0">
        <geom name="world_x_axis" type="capsule" fromto="0 0 0 0.15 0 0" size="0.01" rgba="1 0 0 1" contype="0" conaffinity="0"/>
        <geom name="world_y_axis" type="capsule" fromto="0 0 0 0 0.15 0" size="0.01" rgba="0 1 0 1" contype="0" conaffinity="0"/>
        <geom name="world_z_axis" type="capsule" fromto="0 0 0 0 0 0.15" size="0.01" rgba="0 0 1 1" contype="0" conaffinity="0"/>
    </body>

  <light name="spotlight" mode="targetbodycom" target="wrist_2_link" pos="0 -1 2"/>
    <body name="base" quat="0 0 0 -1" childclass="ur5e">
      <inertial mass="4.0" pos="0 0 0" diaginertia="0.00443333156 0.00443333156 0.0072"/>
      <!-- Reference frame: base -->
      <geom type="capsule" fromto="0 0 0 0.08 0 0" rgba="1 0 0 1" size="0.003" contype="0" conaffinity="0"/>
      <geom type="capsule" fromto="0 0 0 0 0.08 0" rgba="0 1 0 1" size="0.003" contype="0" conaffinity="0"/>
      <geom type="capsule" fromto="0 0 0 0 0 0.08" rgba="0 0 1 1" size="0.003" contype="0" conaffinity="0"/>
      <geom mesh="base_0" material="black" class="visual"/>
      <geom mesh="base_1" material="jointgray" class="visual"/>
      <body name="shoulder_link" pos="0 0 0.163">
        <inertial mass="3.7" pos="0 0 0" diaginertia="0.0102675 0.0102675 0.00666"/>
        <!-- Reference frame: shoulder_link -->
        <!--<geom type="capsule" fromto="0 0 0 0.08 0 0" rgba="1 0 0 1" size="0.003" contype="0" conaffinity="0"/>
        <geom type="capsule" fromto="0 0 0 0 0.08 0" rgba="0 1 0 1" size="0.003" contype="0" conaffinity="0"/>
        <geom type="capsule" fromto="0 0 0 0 0 0.08" rgba="0 0 1 1" size="0.003" contype="0" conaffinity="0"/> -->
        <joint name="shoulder_pan_joint" class="size3" axis="0 0 1"/>
        <geom mesh="shoulder_0" material="urblue" class="visual"/>
        <geom mesh="shoulder_1" material="black" class="visual"/>
        <geom mesh="shoulder_2" material="jointgray" class="visual"/>
        <geom name="shoulder_collision" class="collision" size="0.06 0.06" pos="0 0 -0.04"/>
        <body name="upper_arm_link" pos="0 0.138 0" quat="1 0 1 0">
          <inertial mass="8.393" pos="0 0 0.2125" diaginertia="0.133886 0.133886 0.0151074"/>
          <!-- Reference frame: upper_arm_link -->
          <!-- <geom type="capsule" fromto="0 0 0 0.08 0 0" rgba="1 0 0 1" size="0.003" contype="0" conaffinity="0"/>
          <geom type="capsule" fromto="0 0 0 0 0.08 0" rgba="0 1 0 1" size="0.003" contype="0" conaffinity="0"/>
          <geom type="capsule" fromto="0 0 0 0 0 0.08" rgba="0 0 1 1" size="0.003" contype="0" conaffinity="0"/> -->
          <joint name="shoulder_lift_joint" class="size3"/>
          <geom mesh="upperarm_0" material="linkgray" class="visual"/>
          <geom mesh="upperarm_1" material="black" class="visual"/>
          <geom mesh="upperarm_2" material="jointgray" class="visual"/>
          <geom mesh="upperarm_3" material="urblue" class="visual"/>
          <geom name="upper_arm_collision_outer" class="collision" pos="0 -0.04 0" quat="1 1 0 0" size="0.06 0.06"/>
          <geom name="upper_arm_collision_inner" class="collision" size="0.05 0.2" pos="0 0 0.2"/>
          <body name="forearm_link" pos="0 -0.131 0.425">
            <inertial mass="2.275" pos="0 0 0.196" diaginertia="0.0311796 0.0311796 0.004095"/>
            <!-- Reference frame: forearm_link -->
            <!-- <geom type="capsule" fromto="0 0 0 0.08 0 0" rgba="1 0 0 1" size="0.003" contype="0" conaffinity="0"/>
            <geom type="capsule" fromto="0 0 0 0 0.08 0" rgba="0 1 0 1" size="0.003" contype="0" conaffinity="0"/>
            <geom type="capsule" fromto="0 0 0 0 0 0.08" rgba="0 0 1 1" size="0.003" contype="0" conaffinity="0"/> -->
            <joint name="elbow_joint" class="size3_limited"/>
            <geom mesh="forearm_0" material="urblue" class="visual"/>
            <geom mesh="forearm_1" material="linkgray" class="visual"/>
            <geom mesh="forearm_2" material="black" class="visual"/>
            <geom mesh="forearm_3" material="jointgray" class="visual"/>
            <geom name="forearm_collision_outer" class="collision" pos="0 0.08 0" quat="1 1 0 0" size="0.055 0.06"/>
            <geom name="forearm_collision_inner" class="collision" size="0.038 0.19" pos="0 0 0.2"/>
            <body name="wrist_1_link" pos="0 0 0.392" quat="1 0 1 0">
              <inertial mass="1.219" pos="0 0.127 0" diaginertia="0.0025599 0.0025599 0.0021942"/>
              <!-- Reference frame: wrist_1_link -->
              <!-- <geom type="capsule" fromto="0 0 0 0.08 0 0" rgba="1 0 0 1" size="0.003" contype="0" conaffinity="0"/>
              <geom type="capsule" fromto="0 0 0 0 0.08 0" rgba="0 1 0 1" size="0.003" contype="0" conaffinity="0"/>
              <geom type="capsule" fromto="0 0 0 0 0 0.08" rgba="0 0 1 1" size="0.003" contype="0" conaffinity="0"/> -->
              <joint name="wrist_1_joint" class="size1"/>
              <geom mesh="wrist1_0" material="black" class="visual"/>
              <geom mesh="wrist1_1" material="urblue" class="visual"/>
              <geom mesh="wrist1_2" material="jointgray" class="visual"/>
              <geom name="wrist_1_collision" class="collision" pos="0 0.05 0" quat="1 1 0 0" size="0.05 0.07"/>
              <body name="wrist_2_link" pos="0 0.127 0">
                <inertial mass="1.219" pos="0 0 0.1" diaginertia="0.0025599 0.0025599 0.0021942"/>
                <!-- Reference frame: wrist_2_link -->
                <!-- <geom type="capsule" fromto="0 0 0 0.08 0 0" rgba="1 0 0 1" size="0.003" contype="0" conaffinity="0"/>
                <geom type="capsule" fromto="0 0 0 0 0.08 0" rgba="0 1 0 1" size="0.003" contype="0" conaffinity="0"/>
                <geom type="capsule" fromto="0 0 0 0 0 0.08" rgba="0 0 1 1" size="0.003" contype="0" conaffinity="0"/> -->
                <joint name="wrist_2_joint" axis="0 0 1" class="size1"/>
                <geom mesh="wrist2_0" material="black" class="visual"/>
                <geom mesh="wrist2_1" material="urblue" class="visual"/>
                <geom mesh="wrist2_2" material="jointgray" class="visual"/>
                <geom name="wrist_2_collision_lower" class="collision" size="0.04 0.06" pos="0 0 0.04"/>
                <geom name="wrist_2_collision_upper" class="collision" pos="0 0.02 0.1" quat="1 1 0 0" size="0.04 0.04"/>
                <body name="wrist_3_link" pos="0 0 0.1">
                  <inertial mass="0.1889" pos="0 0.0771683 0" quat="1 0 0 1" diaginertia="0.000132134 9.90863e-05 9.90863e-05"/>
                  <!-- Reference frame: wrist_3_link -->
                  <!-- <geom type="capsule" fromto="0 0 0 0.08 0 0" rgba="1 0 0 1" size="0.003" contype="0" conaffinity="0"/>
                  <geom type="capsule" fromto="0 0 0 0 0.08 0" rgba="0 1 0 1" size="0.003" contype="0" conaffinity="0"/>
                  <geom type="capsule" fromto="0 0 0 0 0 0.08" rgba="0 0 1 1" size="0.003" contype="0" conaffinity="0"/> -->
                  <joint name="wrist_3_joint" class="size1"/>
                  <geom material="linkgray" mesh="wrist3" class="visual"/>
                  <geom name="wrist_3_collision" class="eef_collision" pos="0 0.08 0" quat="1 1 0 0" size="0.04 0.02"/>
                  <site name="ee_site" pos="0 0.1 0" quat="0.7071 -0.7071 0 0"/>
                  <body name="ee_frame_visual_only" pos="0 0.1 0" quat="0.7071 -0.7071 0 0">
                      <geom type="capsule" fromto="0 0 0 0.05 0 0" rgba="1 0 0 1" size="0.002" contype="0" conaffinity="0"/>
                      <geom type="capsule" fromto="0 0 0 0 0.05 0" rgba="0 1 0 1" size="0.002" contype="0" conaffinity="0"/>
                      <geom type="capsule" fromto="0 0 0 0 0 0.05" rgba="0 0 1 1" size="0.002" contype="0" conaffinity="0"/>
                      <!-- The tool is imported by a python code -->
                      
                      
                      <!-- Reference frame attached @ tool tip for screwing (T) -->
                      <body name="tool_frame" pos="0 0 0" quat="1 0 0 0">
                        <site name="tool_site" pos="0 0 0" quat="1 0 0 0"/>
                        <geom type="capsule" fromto="0 0 0 0.06 0 0" rgba="1 0 0 1" size="0.003" contype="0" conaffinity="0"/>
                        <geom type="capsule" fromto="0 0 0 0 0.06 0" rgba="0 1 0 1" size="0.003" contype="0" conaffinity="0"/>
                        <geom type="capsule" fromto="0 0 0 0 0 0.06" rgba="0 0 1 1" size="0.003" contype="0" conaffinity="0"/>
                    </body>
                  <body name="tool_top" pos="0 0 0">
      <inertial mass="2.6" pos="0 0 0.155" diaginertia="0.0143 0.0143 0.0016"/>
      <geom type="mesh" mesh="tool_mesh" rgba="0.2 0.2 0.2 1" contype="0" conaffinity="0" group="0"/>
      <!-- collision cylinder -->
      <geom name="screwdriver" type="cylinder" size="0.035 0.155" pos="0 0 0.155" rgba="0.2 0.8 0.2 1" contype="1" conaffinity="1" group="3"/>
      <!-- Marker (red sphere) to specify the origin -->
      <site name="mount_site" pos="0 0 0" size="0.005" rgba="1 0 0 1"/>
      <!-- Marker (green sphere) to specify the point of application of the weight -->
      <geom type="sphere" size="0.005" pos="0 0 0.125" rgba="0 1 0 1" contype="0" conaffinity="0" group="2"/>
    </body>
  </body>
                </body>
              </body>
            </body>
          </body>
        </body>
      </body>
    </body>
  <body name="table_grip" pos="0 0 0">

      <geom type="mesh" mesh="table_grip_mesh" rgba="0.45 0.45 0.45 1" contype="0" conaffinity="0" group="0"/>

      <!-- Base plate -->
      <geom name="base_plate" type="box" size="0.09 0.175 0.02" pos="0 0 0.02" rgba="0.8 0.2 0.2 1" contype="1" conaffinity="1" group="3"/>

      <!-- Central support -->
      <geom name="central_support" type="box" size="0.075 0.035 0.055" pos="0 0 0.095" rgba="0.2 0.8 0.2 1" contype="1" conaffinity="1" group="3"/>

      <!-- Lateral support -->
      <geom name="lateral_support" type="box" size="0.0925 0.015 0.0325" pos="0.0525 0.05 0.0825" rgba="0.2 0.2 0.8 1" contype="1" conaffinity="1" group="3"/>

      <!-- Upper support -->
      <geom name="upper_support" type="box" size="0.1 0.066 0.0275" pos="0 -0.049 0.1775" rgba="0.7 0.7 0.0 1" contype="1" conaffinity="1" group="3"/>


      <!-- Definition of the sites -->
      <!-- center of the piece -->
      <site name="mount_plate_site" pos="0.0 0.0 0.0" size="0.005" rgba="1 0 0 1"/>

      <!-- Hole 1 -->
      <body name="hole_1_frame_body" pos="0 0.14 0.06" quat="0 1 0 0">
        <geom type="capsule" fromto="0 0 0 0.08 0 0" rgba="1 0 0 1" size="0.003" contype="0" conaffinity="0"/>
        <geom type="capsule" fromto="0 0 0 0 0.08 0" rgba="0 1 0 1" size="0.003" contype="0" conaffinity="0"/>
        <geom type="capsule" fromto="0 0 0 0 0 0.08" rgba="0 0 1 1" size="0.003" contype="0" conaffinity="0"/>
      </body>

      <!-- Hole 2 -->
      <body name="hole_2_frame_body" pos="0.155 0.05 0.107" quat="0.7071 0 -0.7071 0">
        <geom type="capsule" fromto="0 0 0 0.08 0 0" rgba="1 0 0 1" size="0.003" contype="0" conaffinity="0"/>
        <geom type="capsule" fromto="0 0 0 0 0.08 0" rgba="0 1 0 1" size="0.003" contype="0" conaffinity="0"/>
        <geom type="capsule" fromto="0 0 0 0 0 0.08" rgba="0 0 1 1" size="0.003" contype="0" conaffinity="0"/>
      </body>

      <!-- Hole 3 -->
      <body name="hole_3_frame_body" pos="0.0 0.039 0.182" quat="0.38268 0.9239 0 0">
        <geom type="capsule" fromto="0 0 0 0.08 0 0" rgba="1 0 0 1" size="0.003" contype="0" conaffinity="0"/>
        <geom type="capsule" fromto="0 0 0 0 0.08 0" rgba="0 1 0 1" size="0.003" contype="0" conaffinity="0"/>
        <geom type="capsule" fromto="0 0 0 0 0 0.08" rgba="0 0 1 1" size="0.003" contype="0" conaffinity="0"/>
      </body>

      <!-- Hole 4 -->
      <body name="hole_4_frame_body" pos="0.0 -0.135 0.193" quat="0.7071 -0.7071 0 0">
        <geom type="capsule" fromto="0 0 0 0.08 0 0" rgba="1 0 0 1" size="0.003" contype="0" conaffinity="0"/>
        <geom type="capsule" fromto="0 0 0 0 0.08 0" rgba="0 1 0 1" size="0.003" contype="0" conaffinity="0"/>
        <geom type="capsule" fromto="0 0 0 0 0 0.08" rgba="0 0 1 1" size="0.003" contype="0" conaffinity="0"/>
      </body>



    </body>   
  </worldbody>

<default><default class="ur5e">
      <material specular="0.5" shininess="0.25"/>
      <joint axis="0 1 0" range="-6.28319 6.28319" armature="0.1"/>
      <general gaintype="fixed" biastype="affine" ctrlrange="-6.2831 6.2831" gainprm="2000" biasprm="0 -2000 -400" forcerange="-150 150"/>
      <default class="size3">
        <default class="size3_limited">
          <joint range="-3.1415 3.1415"/>
          <general ctrlrange="-3.1415 3.1415"/>
        </default>
      </default>
      <default class="size1">
        <general gainprm="500" biasprm="0 -500 -100" forcerange="-28 28"/>
      </default>
      <default class="visual">
        <geom type="mesh" contype="0" conaffinity="0" group="2"/>
      </default>
      <default class="collision">
        <geom type="capsule" group="3"/>
        <default class="eef_collision">
          <geom type="cylinder"/>
        </default>
      </default>
      <site size="0.001" rgba="0.5 0.5 0.5 0.3" group="4"/>
    </default>
  <geom condim="3" friction="1 0.5 0.01" solref="0.02 1" solimp="0.9 0.95 0.001"/>
  </default><actuator><motor joint="shoulder_pan_joint" gear="1"/>
    <motor joint="shoulder_lift_joint" gear="1"/>
    <motor joint="elbow_joint" gear="1"/>
    <motor joint="wrist_1_joint" gear="1"/>
    <motor joint="wrist_2_joint" gear="1"/>
    <motor joint="wrist_3_joint" gear="1"/>
  </actuator></mujoco>
